Error date [2020, 4, 29]

Traceback (most recent call last):
  File "trback.py", line 6, in <module>
    raise Exception('error has occurred')
Exception: error has occurred
